ERROR:root:Error procesando MJ
Traceback (most recent call last):
  File "C:\Users\Feragon\Documents\GitHub\descarga-nominas-rd\.venv\Lib\site-packages\urllib3\connection.py", line 203, in _new_conn
    sock = connection.create_connection(
           ^^^^^^^^^^^^^^^^^^^^^^^^^^^^^
  File "C:\Users\Feragon\Documents\GitHub\descarga-nominas-rd\.venv\Lib\site-packages\urllib3\util\connection.py", line 60, in create_connection
    for res in socket.getaddrinfo(host, port, family, socket.SOCK_STREAM):
               ^^^^^^^^^^^^^^^^^^^^^^^^^^^^^^^^^^^^^^^^^^^^^^^^^^^^^^^^^^
  File "c:\Users\Feragon\AppData\Local\Programs\Python\Python312\Lib\socket.py", line 963, in getaddrinfo
    for res in _socket.getaddrinfo(host, port, family, type, proto, flags):
               ^^^^^^^^^^^^^^^^^^^^^^^^^^^^^^^^^^^^^^^^^^^^^^^^^^^^^^^^^^^
socket.gaierror: [Errno 11001] getaddrinfo failed

The above exception was the direct cause of the following exception:

Traceback (most recent call last):
  File "C:\Users\Feragon\Documents\GitHub\descarga-nominas-rd\.venv\Lib\site-packages\urllib3\connectionpool.py", line 790, in urlopen
    response = self._make_request(
               ^^^^^^^^^^^^^^^^^^^
  File "C:\Users\Feragon\Documents\GitHub\descarga-nominas-rd\.venv\Lib\site-packages\urllib3\connectionpool.py", line 491, in _make_request
    raise new_e
  File "C:\Users\Feragon\Documents\GitHub\descarga-nominas-rd\.venv\Lib\site-packages\urllib3\connectionpool.py", line 467, in _make_request
    self._validate_conn(conn)
  File "C:\Users\Feragon\Documents\GitHub\descarga-nominas-rd\.venv\Lib\site-packages\urllib3\connectionpool.py", line 1096, in _validate_conn
    conn.connect()
  File "C:\Users\Feragon\Documents\GitHub\descarga-nominas-rd\.venv\Lib\site-packages\urllib3\connection.py", line 611, in connect
    self.sock = sock = self._new_conn()
                       ^^^^^^^^^^^^^^^^
  File "C:\Users\Feragon\Documents\GitHub\descarga-nominas-rd\.venv\Lib\site-packages\urllib3\connection.py", line 210, in _new_conn
    raise NameResolutionError(self.host, self, e) from e
urllib3.exceptions.NameResolutionError: <urllib3.connection.HTTPSConnection object at 0x0000020C564C64B0>: Failed to resolve 'juventud.gob.dohttps' ([Errno 11001] getaddrinfo failed)

The above exception was the direct cause of the following exception:

Traceback (most recent call last):
  File "C:\Users\Feragon\Documents\GitHub\descarga-nominas-rd\.venv\Lib\site-packages\requests\adapters.py", line 486, in send
    resp = conn.urlopen(
           ^^^^^^^^^^^^^
  File "C:\Users\Feragon\Documents\GitHub\descarga-nominas-rd\.venv\Lib\site-packages\urllib3\connectionpool.py", line 844, in urlopen
    retries = retries.increment(
              ^^^^^^^^^^^^^^^^^^
  File "C:\Users\Feragon\Documents\GitHub\descarga-nominas-rd\.venv\Lib\site-packages\urllib3\util\retry.py", line 515, in increment
    raise MaxRetryError(_pool, url, reason) from reason  # type: ignore[arg-type]
    ^^^^^^^^^^^^^^^^^^^^^^^^^^^^^^^^^^^^^^^^^^^^^^^^^^^
urllib3.exceptions.MaxRetryError: HTTPSConnectionPool(host='juventud.gob.dohttps', port=443): Max retries exceeded with url: //juventud.gob.do/transparencia/download/nomina-fija-febrero-2024/ (Caused by NameResolutionError("<urllib3.connection.HTTPSConnection object at 0x0000020C564C64B0>: Failed to resolve 'juventud.gob.dohttps' ([Errno 11001] getaddrinfo failed)"))

During handling of the above exception, another exception occurred:

Traceback (most recent call last):
  File "c:\Users\Feragon\Documents\GitHub\descarga-nominas-rd\download_functions.py", line 851, in <module>
    eval(f"download_{df['nombre_corto'][i].lower()}")()
  File "c:\Users\Feragon\Documents\GitHub\descarga-nominas-rd\download_functions.py", line 829, in download_mj
    download_excel_files_from_url(available_links,folder_name)
  File "c:\Users\Feragon\Documents\GitHub\descarga-nominas-rd\utils.py", line 132, in download_excel_files_from_url
    r = requests.get(link, allow_redirects=allow_redirects, headers=headers,verify=False)
        ^^^^^^^^^^^^^^^^^^^^^^^^^^^^^^^^^^^^^^^^^^^^^^^^^^^^^^^^^^^^^^^^^^^^^^^^^^^^^^^^^
  File "C:\Users\Feragon\Documents\GitHub\descarga-nominas-rd\.venv\Lib\site-packages\requests\api.py", line 73, in get
    return request("get", url, params=params, **kwargs)
           ^^^^^^^^^^^^^^^^^^^^^^^^^^^^^^^^^^^^^^^^^^^^
  File "C:\Users\Feragon\Documents\GitHub\descarga-nominas-rd\.venv\Lib\site-packages\requests\api.py", line 59, in request
    return session.request(method=method, url=url, **kwargs)
           ^^^^^^^^^^^^^^^^^^^^^^^^^^^^^^^^^^^^^^^^^^^^^^^^^
  File "C:\Users\Feragon\Documents\GitHub\descarga-nominas-rd\.venv\Lib\site-packages\requests\sessions.py", line 589, in request
    resp = self.send(prep, **send_kwargs)
           ^^^^^^^^^^^^^^^^^^^^^^^^^^^^^^
  File "C:\Users\Feragon\Documents\GitHub\descarga-nominas-rd\.venv\Lib\site-packages\requests\sessions.py", line 703, in send
    r = adapter.send(request, **kwargs)
        ^^^^^^^^^^^^^^^^^^^^^^^^^^^^^^^
  File "C:\Users\Feragon\Documents\GitHub\descarga-nominas-rd\.venv\Lib\site-packages\requests\adapters.py", line 519, in send
    raise ConnectionError(e, request=request)
requests.exceptions.ConnectionError: HTTPSConnectionPool(host='juventud.gob.dohttps', port=443): Max retries exceeded with url: //juventud.gob.do/transparencia/download/nomina-fija-febrero-2024/ (Caused by NameResolutionError("<urllib3.connection.HTTPSConnection object at 0x0000020C564C64B0>: Failed to resolve 'juventud.gob.dohttps' ([Errno 11001] getaddrinfo failed)"))
